<?xml version="1.0" ?>
<robot name="books_demo"
       xmlns:controller="http://playerstage.sourceforge.net/gazebo/xmlschema/#controller" 
       xmlns:interface="http://playerstage.sourceforge.net/gazebo/xmlschema/#interface" 
       xmlns:sensor="http://playerstage.sourceforge.net/gazebo/xmlschema/#sensor" 
       xmlns:xacro="http://www.ros.org/wiki/xacro">

  <!-- 
       ROS URDF model of several books.
       Origin and center of mass are at the center of the mesh.

       (C) 2019 fnh, hendrich@informatik.uni-hamburg.de
  -->
  <!-- main body with Collada mesh for both visual and collision -->

  <xacro:include filename="$(find tams_books_world)/urdf/book_cube.xacro" />

  <xacro:book_cube 
      name="book_bobh"
      weight="0.210"
      mesh="book-bobh.dae"
      xsize="0.126"
      ysize="0.010"
      zsize="0.184"
  />

  <xacro:book_cube 
      name="book_dyson"
      weight="0.228"
      mesh="book-dyson.dae"
      xsize="0.130"
      ysize="0.018"
      zsize="0.198"
  />

  <xacro:book_cube 
      name="book_goedel"
      weight="1.100"
      mesh="book-goedel.dae"
      xsize="0.162"
      ysize="0.055"
      zsize="0.234"
  />

  <xacro:book_cube 
      name="book_hamburg"
      weight="0.062"
      mesh="book-hamburg.dae"
      xsize="0.108"
      ysize="0.005"
      zsize="0.185"
  />

  <xacro:book_cube 
      name="book_haykin"
      weight="1.316"
      mesh="book-haykin.dae"
      xsize="0.177"
      ysize="0.032"
      zsize="0.230"
  />

  <xacro:book_cube 
      name="book_javaff"
      weight="0.906"
      mesh="book-javaff.dae"
      xsize="0.157"
      ysize="0.034"
      zsize="0.235"
  />

  <xacro:book_cube 
      name="book_jekyll"
      weight="0.056"
      mesh="book-jekyll.dae"
      xsize="0.110"
      ysize="0.007"
      zsize="0.180"
  />

  <xacro:book_cube 
      name="book_knuth_40"
      weight="0.400"
      mesh="book-knuth-40.dae"
      xsize="0.161"
      ysize="0.014"
      zsize="0.240"
  />

  <xacro:book_cube 
      name="book_knuth_41"
      weight="0.498"
      mesh="book-knuth-41.dae"
      xsize="0.161"
      ysize="0.017"
      zsize="0.240"
  />


  <xacro:book_cube 
      name="book_knuth_42"
      weight="0.274"
      mesh="book-knuth-42.dae"
      xsize="0.161"
      ysize="0.009"
      zsize="0.240"
  />

  <xacro:book_cube 
      name="book_knuth"
      weight="1.080"
      mesh="book-knuth.dae"
      xsize="0.167"
      ysize="0.037"
      zsize="0.240"
  />

  <xacro:book_cube 
      name="book_lagemann"
      weight="0.554"
      mesh="book-lagemann.dae"
      xsize="0.165"
      ysize="0.015"
      zsize="0.242"
  />

  <xacro:book_cube 
      name="book_lakoff"
      weight="0.977"
      mesh="book-lakoff.dae"
      xsize="0.168"
      ysize="0.035"
      zsize="0.240"
  />

  <xacro:book_cube 
      name="book_lskm"
      weight="0.978"
      mesh="book-lskm.dae"
      xsize="0.217"
      ysize="0.024"
      zsize="0.250"
  />

  <xacro:book_cube 
      name="book_mead_conway"
      weight="0.972"
      mesh="book-mead-conway.dae"
      xsize="0.200"
      ysize="0.025"
      zsize="0.243"
  />

  <xacro:book_cube 
      name="book_memory"
      weight="0.666"
      mesh="book-memory.dae"
      xsize="0.148"
      ysize="0.028"
      zsize="0.227"
  />

  <xacro:book_cube 
      name="book_minsky"
      weight="0.764"
      mesh="book-minsky.dae"
      xsize="0.215"
      ysize="0.019"
      zsize="0.280"
  />

  <xacro:book_cube 
      name="book_moeller"
      weight="0.592"
      mesh="book-moeller.dae"
      xsize="0.153"
      ysize="0.023"
      zsize="0.236"
  />

  <xacro:book_cube 
      name="book_pdp1"
      weight="0.897"
      mesh="book-pdp1.dae"
      xsize="0.150"
      ysize="0.032"
      zsize="0.228"
  />

  <xacro:book_cube 
      name="book_pdp2"
      weight="1.008"
      mesh="book-pdp2.dae"
      xsize="0.150"
      ysize="0.036"
      zsize="0.228"
  />

  <xacro:book_cube 
      name="book_rojas"
      weight="0.666"
      mesh="book-rojas.dae"
      xsize="0.155"
      ysize="0.030"
      zsize="0.232"
  />

  <xacro:book_cube 
      name="book_schmidt"
      weight="1.764"
      mesh="book-schmidt.dae"
      xsize="0.200"
      ysize="0.038"
      zsize="0.275"
  />

  <xacro:book_cube 
      name="book_selfish"
      weight="0.246"
      mesh="book-selfish.dae"
      xsize="0.130"
      ysize="0.020"
      zsize="0.196"
  />

  <xacro:book_cube 
      name="book_voynich"
      weight="2.0"
      mesh="voynich/book-voynich.dae"
      xsize="0.160"
      ysize="0.057"
      zsize="0.230"
  />

  <xacro:book_cube 
      name="book_watson"
      weight="0.114"
      mesh="book-watson.dae"
      xsize="0.115"
      ysize="0.010"
      zsize="0.190"
  />

  <xacro:book_cube 
      name="book_wiering"
      weight="0.964"
      mesh="book-wiering.dae"
      xsize="0.155"
      ysize="0.035"
      zsize="0.235"
  />

  <xacro:book_cube 
      name="book_winograd"
      weight="0.777"
      mesh="book-winograd.dae"
      xsize="0.168"
      ysize="0.037"
      zsize="0.240"
  />

  <xacro:book_cube 
      name="book_zuse"
      weight="0.764"
      mesh="book-zuse.dae"
      xsize="0.172"
      ysize="0.021"
      zsize="0.247"
  />


  <link name="world" />

  <joint name="world_bobh_joint" type="floating">
     <parent link="world" />
     <child  link="book_bobh_link" />
     <origin xyz="0 0.1 0.4" rpy="0 0.1 0" />
  </joint>

  <joint name="world_dyson_joint" type="floating">
     <parent link="world" />
     <child  link="book_dyson_link" />
     <origin xyz="0 0.2 0.4" rpy="0 0.2 0" />
  </joint>

  <joint name="world_hamburg_joint" type="floating">
     <parent link="world" />
     <child  link="book_hamburg_link" />
     <origin xyz="0 0.3 0.4" rpy="0 0.3 0" />
  </joint>

  <joint name="world_haykin_joint" type="floating">
     <parent link="world" />
     <child  link="book_haykin_link" />
     <origin xyz="0 0.4 0.4" rpy="0 0.4 0" />
  </joint>

  <joint name="world_javaff_joint" type="floating">
     <parent link="world" />
     <child  link="book_javaff_link" />
     <origin xyz="0 0.5 0.4" rpy="0 0.5 0" />
  </joint>

  <joint name="world_jekyll_joint" type="floating">
     <parent link="world" />
     <child  link="book_jekyll_link" />
     <origin xyz="0 0.6 0.4" rpy="0 0.6 0" />
  </joint>

  <joint name="world_goedel_joint" type="floating">
     <parent link="world" />
     <child  link="book_goedel_link" />
     <origin xyz="0 0.7 0.4" rpy="0 0.7 0" />
  </joint>






  <joint name="world_knuth_40_joint" type="floating">
     <parent link="world" />
     <child  link="book_knuth_40_link" />
     <origin xyz="0.3 0 0.4" rpy="0.0 0 0" />
  </joint>

  <joint name="world_knuth_41_joint" type="floating">
     <parent link="world" />
     <child  link="book_knuth_41_link" />
     <origin xyz="0.3 0.1 0.4" rpy="0 0.1 0" />
  </joint>

  <joint name="world_knuth_42_joint" type="floating">
     <parent link="world" />
     <child  link="book_knuth_42_link" />
     <origin xyz="0.3 0.2 0.4" rpy="0 0.2 0" />
  </joint>

  <joint name="world_knuth_joint" type="floating">
     <parent link="world" />
     <child  link="book_knuth_link" />
     <origin xyz="0.3 0.3 0.4" rpy="0 0.3 0" />
  </joint>

  <joint name="world_lagemann_joint" type="floating">
     <parent link="world" />
     <child  link="book_lagemann_link" />
     <origin xyz="0.3 0.4 0.3" rpy="0 0.4 0" />
  </joint>

  <joint name="world_lskm_joint" type="floating">
     <parent link="world" />
     <child  link="book_lskm_link" />
     <origin xyz="0.3 0.5 0.3" rpy="0.5 0.5 0" />
  </joint>

  <joint name="world_memory_joint" type="floating">
     <parent link="world" />
     <child  link="book_memory_link" />
     <origin xyz="1 1.2 0.3" rpy="0 0 0.6" />
  </joint>

  <joint name="world_moeller_joint" type="floating">
     <parent link="world" />
     <child  link="book_moeller_link" />
     <origin xyz="1 1 0.3" rpy="0 0 0.6" />
  </joint>

  <joint name="world_minsky_joint" type="floating">
     <parent link="world" />
     <child  link="book_minsky_link" />
     <origin xyz="0 1 0.3" rpy="-0.5 0 0" />
  </joint>

  <joint name="world_rojas_joint" type="floating">
     <parent link="world" />
     <child  link="book_rojas_link" />
     <origin xyz="0.6 1 0.3" rpy="0.0 0 0" />
  </joint>

  <joint name="world_selfish_joint" type="floating">
     <parent link="world" />
     <child  link="book_selfish_link" />
     <origin xyz="0.6 0 0.3" rpy="0.0 0 0" />
  </joint>

  <joint name="world_watson_joint" type="floating">
     <parent link="world" />
     <child  link="book_watson_link" />
     <origin xyz="0.6 0.1 0.3" rpy="0 0.1 0" />
  </joint>

  <joint name="world_wiering_joint" type="floating">
     <parent link="world" />
     <child  link="book_wiering_link" />
     <origin xyz="0.6 0.2 0.3" rpy="0 0.2 0" />
  </joint>

  <joint name="world_zuse_joint" type="floating">
     <parent link="world" />
     <child  link="book_zuse_link" />
     <origin xyz="0.8 0.3 0.3" rpy="-0.3 0.8 0" />
  </joint>

  <!-- newcomers -->

  <joint name="world_pdp1_joint" type="floating">
     <parent link="world" />
     <child  link="book_pdp1_link" />
     <origin xyz="1.1 0.0 0.4" rpy="-0.3 0.0 0" />
  </joint>

  <joint name="world_pdp2_joint" type="floating">
     <parent link="world" />
     <child  link="book_pdp2_link" />
     <origin xyz="1.1 0.1 0.3" rpy="-0.1 0.1 0" />
  </joint>

  <joint name="world_voynich_joint" type="floating">
     <parent link="world" />
     <child  link="book_voynich_link" />
     <origin xyz="1.1 0.2 0.5" rpy="-0.2 0.2 0" />
  </joint>

  <joint name="world_winograd_joint" type="floating">
     <parent link="world" />
     <child  link="book_winograd_link" />
     <origin xyz="1.1 0.3 0.3" rpy="-0.2 0.2 0" />
  </joint>

  <joint name="world_schmidt_joint" type="floating">
     <parent link="world" />
     <child  link="book_schmidt_link" />
     <origin xyz="1.1 0.4 0.4" rpy="-0.3 0.3 0" />
  </joint>

  <joint name="world_lakoff_joint" type="floating">
     <parent link="world" />
     <child  link="book_lakoff_link" />
     <origin xyz="1.1 0.5 0.4" rpy="-0.5 0.5 0" />
  </joint>

  <joint name="world_mead_conway_joint" type="floating">
     <parent link="world" />
     <child  link="book_mead_conway_link" />
     <origin xyz="1.1 0.6 0.4" rpy="-0.6 0.6 0" />
  </joint>

</robot>

